<?xml version="1.0" ?>
<!-- =================================================================================== -->
<!-- |    This document was autogenerated by xacro from demo_cartesian.urdf.xacro      | -->
<!-- |    EDITING THIS FILE BY HAND IS NOT RECOMMENDED                                 | -->
<!-- =================================================================================== -->
<!-- Author:  Raul Cruz-Oliver, rcruzoliver@student.ethz.ch -->
<!-- Date, place:  November 2023, Butikkon, CH -->
<robot name="printer_v1">
  <!-- Define properties -->
  <!-- <xacro:property name="pi" value="3.1415926535" />  checked, does not need to redefine in humble-->
  <!-- checked -->
  <!-- checked -->
  <!-- approx -->
  <!-- approx -->
  <!-- approx -->
  <!-- approx -->
  <!-- approx -->
  <!-- approx -->
  <!-- approx -->
  <!-- approx -->
  <!-- approx -->
  <!-- approx -->
  <!-- Links-->
  <link name="granite">
    <pose>0 0 0 0 0 0</pose>
    <visual>
      <origin xyz="0 0 0"/>
      <geometry>
        <box size="0.4 0.4 0.03"/>
      </geometry>
      <material name="grey">
        <color rgba="0.5 0.5 0.5 1"/>
      </material>
    </visual>
    <collision>
      <origin xyz="0 0 0"/>
      <geometry>
        <box size="0.4 0.4 0.03"/>
      </geometry>
    </collision>
    <inertial>
      <mass value="0.050"/>
      <origin xyz="0 0 0"/>
      <inertia ixx="0.01" ixy="0.0" ixz="0.0" iyy="0.01" iyz="0.0" izz="0.01"/>
    </inertial>
  </link>
  <link name="base">
    <visual>
      <geometry>
        <box size="0.35 0.35 0.015"/>
      </geometry>
      <material name="grey">
        <color rgba="0.5 0.5 0.5 1"/>
      </material>
    </visual>
    <collision>
      <geometry>
        <box size="0.35 0.35 0.015"/>
      </geometry>
    </collision>
    <inertial>
      <mass value="0.050"/>
      <origin xyz="0 0 0"/>
      <inertia ixx="0.01" ixy="0.0" ixz="0.0" iyy="0.01" iyz="0.0" izz="0.01"/>
    </inertial>
  </link>
  <link name="frame">
    <visual>
      <!-- <origin xyz="0 0 ${frame_size_z/2}" /> -->
      <origin rpy="0 0 0" xyz="-0.155 -0.2090 0"/>
      <geometry>
        <!-- <box size="${frame_size_x} ${frame_size_y} ${frame_size_z}"/> -->
        <mesh filename="package://kr_rviz_demo/meshes/frame.stl"/>
        <scale>0.1 0.1 0.1</scale>
      </geometry>
      <material name="grey">
        <color rgba="0.5 0.5 0.5 1"/>
      </material>
    </visual>
    <collision>
      <!-- <origin xyz="0 0 ${frame_size_z/2}" /> -->
      <origin rpy="0 0 0" xyz="-0.155 -0.2090 0"/>
      <geometry>
        <!-- <box size="${frame_size_x} ${frame_size_y} ${frame_size_z}" /> -->
        <mesh filename="package://kr_rviz_demo/meshes/frame.stl"/>
        <scale>0.1 0.1 0.1</scale>
      </geometry>
    </collision>
    <inertial>
      <mass value="2.0"/>
      <origin xyz="0 0 0"/>
      <inertia ixx="0.01" ixy="0.0" ixz="0.0" iyy="0.01" iyz="0.0" izz="0.01"/>
    </inertial>
  </link>
  <link name="base_y_axis">
    <visual>
      <origin xyz="0 0 0.005"/>
      <geometry>
        <box size="0.06 0.18 0.01"/>
      </geometry>
      <material name="grey">
        <color rgba="1 0 0 1"/>
      </material>
    </visual>
    <collision>
      <origin xyz="0 0 0.005"/>
      <geometry>
        <box size="0.06 0.18 0.01"/>
      </geometry>
    </collision>
    <inertial>
      <mass value="2.0"/>
      <origin xyz="0 0 0"/>
      <inertia ixx="0.01" ixy="0.0" ixz="0.0" iyy="0.01" iyz="0.0" izz="0.01"/>
    </inertial>
  </link>
  <link name="carriage_y_axis">
    <visual>
      <origin xyz="0 0 0.005"/>
      <geometry>
        <box size="0.085 0.11 0.01"/>
      </geometry>
      <material name="grey">
        <color rgba="1 0 0 1"/>
      </material>
    </visual>
    <collision>
      <origin xyz="0 0 0.005"/>
      <geometry>
        <box size="0.085 0.11 0.01"/>
      </geometry>
    </collision>
    <inertial>
      <mass value="2.0"/>
      <origin xyz="0 0 0"/>
      <inertia ixx="0.01" ixy="0.0" ixz="0.0" iyy="0.01" iyz="0.0" izz="0.01"/>
    </inertial>
  </link>
  <link name="carriage_x_axis">
    <visual>
      <origin xyz="0 0 0.01"/>
      <geometry>
        <box size="0.11 0.085 0.02"/>
      </geometry>
      <material name="grey">
        <color rgba="0.5 0.5 0.5 1"/>
      </material>
    </visual>
    <collision>
      <origin xyz="0 0 0.01"/>
      <geometry>
        <box size="0.11 0.085 0.02"/>
      </geometry>
    </collision>
    <inertial>
      <mass value="2.0"/>
      <origin xyz="0 0 0"/>
      <inertia ixx="0.01" ixy="0.0" ixz="0.0" iyy="0.01" iyz="0.0" izz="0.01"/>
    </inertial>
  </link>
  <link name="base_x_axis">
    <visual>
      <origin xyz="0 0 0.005"/>
      <geometry>
        <box size="0.16 0.06 0.01"/>
      </geometry>
      <material name="grey">
        <color rgba="0.5 0.5 0.5 1"/>
      </material>
    </visual>
    <collision>
      <origin xyz="0 0 0.005"/>
      <geometry>
        <box size="0.16 0.06 0.01"/>
      </geometry>
    </collision>
    <inertial>
      <mass value="2.0"/>
      <origin xyz="0 0 0"/>
      <inertia ixx="0.01" ixy="0.0" ixz="0.0" iyy="0.01" iyz="0.0" izz="0.01"/>
    </inertial>
  </link>
  <link name="bed">
    <visual>
      <origin xyz="0 0 0.0025"/>
      <geometry>
        <box size="0.175 0.175 0.005"/>
      </geometry>
      <material name="blue">
        <color rgba="0.5 0.5 0.5 1"/>
      </material>
    </visual>
    <collision>
      <origin xyz="0 0 0.0025"/>
      <geometry>
        <box size="0.175 0.175 0.005"/>
      </geometry>
    </collision>
    <inertial>
      <mass value="2.0"/>
      <origin xyz="0 0 0"/>
      <inertia ixx="0.01" ixy="0.0" ixz="0.0" iyy="0.01" iyz="0.0" izz="0.01"/>
    </inertial>
  </link>
  <link name="carriage_z_axis">
    <visual>
      <origin xyz="0 -0.0125 0"/>
      <geometry>
        <box size="0.065 0.025 0.07"/>
      </geometry>
      <material name="grey">
        <color rgba="0.5 0.5 0.5 1"/>
      </material>
    </visual>
    <collision>
      <origin xyz="0 -0.0125 0"/>
      <geometry>
        <box size="0.065 0.025 0.07"/>
      </geometry>
    </collision>
    <inertial>
      <mass value="2.0"/>
      <origin xyz="0 0 0"/>
      <inertia ixx="0.01" ixy="0.0" ixz="0.0" iyy="0.01" iyz="0.0" izz="0.01"/>
    </inertial>
  </link>
  <link name="base_z_axis">
    <visual>
      <origin xyz="0 -0.01 0"/>
      <geometry>
        <box size="0.04 -0.01 0.08"/>
      </geometry>
      <material name="grey">
        <color rgba="0.5 0.5 0.5 1"/>
      </material>
    </visual>
    <collision>
      <origin xyz="0 -0.01 0"/>
      <geometry>
        <box size="0.04 -0.01 0.08"/>
      </geometry>
    </collision>
    <inertial>
      <mass value="2.0"/>
      <origin xyz="0 0 0"/>
      <inertia ixx="0.01" ixy="0.0" ixz="0.0" iyy="0.01" iyz="0.0" izz="0.01"/>
    </inertial>
  </link>
  <link name="printhead">
    <visual>
      <origin rpy="0 0 0" xyz="0 0 0"/>
      <geometry>
        <box size="0.02 0.02 0.15"/>
      </geometry>
      <material name="blue">
        <color rgba="0.5 0.5 0.5 1"/>
      </material>
    </visual>
    <collision>
      <origin xyz="0 -0.01 0"/>
      <geometry>
        <box size="0.02 0.02 0.15"/>
      </geometry>
    </collision>
    <inertial>
      <mass value="2.0"/>
      <origin xyz="0 0 0"/>
      <inertia ixx="0.01" ixy="0.0" ixz="0.0" iyy="0.01" iyz="0.0" izz="0.01"/>
    </inertial>
  </link>
  <!--
-->
  <!-- Joints -->
  <joint name="granite_to_base" type="fixed">
    <origin rpy="0 0 0" xyz="0.0 0.0 0.015"/>
    <parent link="granite"/>
    <child link="base"/>
  </joint>
  <joint name="base_to_frame" type="fixed">
    <origin rpy="0 0 0" xyz="0.0 0.06737499999999999 0.0075"/>
    <!-- approx -->
    <parent link="base"/>
    <child link="frame"/>
  </joint>
  <joint name="base_to_base_y_axis" type="fixed">
    <origin rpy="0 0 0" xyz="0.0 0.0 0.0075"/>
    <parent link="base"/>
    <child link="base_y_axis"/>
  </joint>
  <joint name="base_y_axis_to_carriage_y_axis" type="prismatic">
    <origin rpy="0 0 0" xyz="0.0 0.0 0.01"/>
    <parent link="base_y_axis"/>
    <child link="carriage_y_axis"/>
    <axis xyz="0 1 0"/>
    <limit effort="10" lower="-0.01" upper="0.01" velocity="1"/>
  </joint>
  <joint name="carriage_y_axis_to_carriage_x_axis" type="fixed">
    <origin rpy="0 0 0" xyz="0.0 0.0 0.01"/>
    <parent link="carriage_y_axis"/>
    <child link="carriage_x_axis"/>
  </joint>
  <joint name="carriage_x_axis_to_base_x_axis" type="prismatic">
    <origin rpy="0 0 0" xyz="0.0 0.0 0.02"/>
    <parent link="carriage_x_axis"/>
    <child link="base_x_axis"/>
    <axis xyz="1 0 0"/>
    <limit effort="10" lower="-0.01" upper="0.01" velocity="1"/>
  </joint>
  <joint name="base_x_axis_to_bed" type="fixed">
    <origin rpy="0 0 0" xyz="0.0 0.0 0.01"/>
    <parent link="base_x_axis"/>
    <child link="bed"/>
  </joint>
  <joint name="frame_to_carriage_z_axis" type="fixed">
    <origin rpy="0 0 0" xyz="0.0 -0.04000000000000001 0.25"/>
    <parent link="frame"/>
    <child link="carriage_z_axis"/>
  </joint>
  <joint name="carriage_z_axis_to_base_z_axis" type="prismatic">
    <origin rpy="0 0 0" xyz="0.0 -0.05 0"/>
    <parent link="carriage_z_axis"/>
    <child link="base_z_axis"/>
    <axis xyz="0 0 1"/>
    <limit effort="100" lower="-0.01" upper="0.01" velocity="0.1"/>
  </joint>
  <joint name="base_z_axis_printhead" type="fixed">
    <origin rpy="0 0 0" xyz="0.0 -0.02 0"/>
    <parent link="base_z_axis"/>
    <child link="printhead"/>
  </joint>
  <!--
-->
</robot>
